# 6주차 문제

## 1. defer 란 무엇인지 설명해주세요.

## 답: 함수가 종료되기 전까지 특정 구문의 실행을 지연시켰다가, 함수가 종료되기 직전에 지연시켰던 구문을 수행

---

## 2.  아래의 조건을 읽고, 오류 타입을 정의하고, 오류(Error)를 던질 수 있는 함수를 만들고 처리해보세요.

1) `idError`, `pwdError` 오류를 가지는 `LoginError` 오류 타입을 정의한다.

2) `id(String)`, `pwd(String)` 파라미터를 가지면서 **오류를 던질 수 있고**, 아웃풋은 **Bool 타입**인 `loginFunction` 함수를 만든다.

 - `id` 가 “aaaa1234” 가 아닌 경우 `idError` 오류를 던지고, `pwd`가 “qwer1234” 가 아닌 경우 `pwdError` 오류를 던진다.

 - `id`가 “aaaa1234”, `pwd`가 “qwer1234” 인 경우 true를 반환한다.

3) do - catch 구문으로 `idError`, `pwdError` 오류를 처리한다.

 - `result` 변수를 만들고, `loginFunction` 함수가 true인 경우 “로그인 되었습니다.” 를 출력한다.

 - `idError` 오류를 던지는 경우 "아이디가 맞지 않습니다.” 를 출력한다.

 - `pwdError` 오류를 던지는 경우 "패스워드가 맞지 않습니다.” 를 출력한다.

4) Id가 일치하지 않을 때, pwd가 일치하지 않을때, 모두 일치할 때의 결과를 출력해보세요.

## 답:

```swift
enum LoginError: Error {
    case idError
    case pwdError
}

func loginFunction(id: String, pwd: String) throws -> Bool {
 
    guard id == "aaaa1234" else { throw LoginError.idError }
    guard pwd == "qwer1234" else { throw LoginError.pwdError }
    return true
    
}

do {
    let result = try loginFunction(id: "aaaa1234", pwd: "qwer1234")
    print("로그인 되었습니다.")
    
} catch LoginError.idError {
    print("아이디가 맞지 않습니다.")
} catch LoginError.pwdError {
    print("패스워드가 맞지 않습니다.")
}
```
